Workbook

Sheet Notes
A1: CulinaAI nutrition engine: phase 1 hand check
A3: What this file does
A4: Ten realistic recipes are calculated here with spreadsheet formulas, straight from CoFID values,
A5: and compared with what the CulinaAI nutrition engine calculated from the ingredient names alone.
A7: Sheets
A8: CoFID: per-100 g values for every food used (blue = values copied from the source dataset).
A9: Recipes: each ingredient row works out its nutrients as grams / 100 x the CoFID value (black = formulas).
A10: Check: per-serving totals from the formulas vs the engine (engine values in blue), and whether they agree.
A12: Rules
A13: A recipe passes when every nutrient differs by less than 0.5% (or 0.05 g / 0.5 kcal for very small values)
A14: and the engine matched every ingredient name to the same CoFID food as this sheet.
A15: Missing CoFID values (e.g. energy for some spices) count as 0, the same as the engine.
... A20: Salt = sodium (mg) x 2.5 / 1000. Fibre = AOAC fibre, or NSP fibre where AOAC is missing.

Sheet Summary
A1: Recipe | B1: Servings | C1: kcal per serving (spreadsheet) | D1: kcal per serving (engine) | E1: All nutrients agree? | F1: Same CoFID foods matched? | G1: Coverage (engine) | H1: Traffic lights (fat / saturates / sugars / salt) | I1: Claims
A2: Garlic chicken and spinach rice bowl | B2: =Check!B2 -> 2 | C2: =Check!D2 -> 606.75 | D2: =Check!E2 -> 606.75 | E2: =IF(COUNTIF(Check!G2:G9,"NO")=0,"Yes","NO") -> Yes | F2: Yes | G2: 1 | H2: amber / green / green / amber | I2: High protein, Low saturated fat, Low sugars
A3: Spaghetti bolognese | B3: =Check!B11 -> 4 | C3: =Check!D11 -> 737.1875 | D3: =Check!E11 -> 737.19 | E3: =IF(COUNTIF(Check!G11:G18,"NO")=0,"Yes","NO") -> Yes | F3: Yes | G3: 1 | H3: red / red / green / green | I3: High protein, Low sugars, Low salt
A4: Chickpea and coconut curry with rice | B4: =Check!B20 -> 4 | C4: =Check!D20 -> 665.8125 | D4: =Check!E20 -> 665.81 | E4: =IF(COUNTIF(Check!G20:G27,"NO")=0,"Yes","NO") -> Yes | F4: Yes | G4: 1 | H4: red / red / green / green | I4: Source of fibre, Low sugars, Low salt
A5: Salmon, new potatoes and broccoli | B5: =Check!B29 -> 2 | C5: =Check!D29 -> 508.6 | D5: =Check!E29 -> 508.6 | E5: =IF(COUNTIF(Check!G29:G36,"NO")=0,"Yes","NO") -> Yes | F5: Yes | G5: 1 | H5: red / red / green / green | I5: High protein, Source of fibre, Low sugars, Low salt
A6: Red lentil dal | B6: =Check!B38 -> 4 | C6: =Check!D38 -> 264.45 | D6: =Check!E38 -> 264.45 | E6: =IF(COUNTIF(Check!G38:G45,"NO")=0,"Yes","NO") -> Yes | F6: Yes | G6: 1 | H6: green / green / green / green | I6: High protein, High fibre, Low fat, Low sugars, Low salt
A7: Cheese and vegetable omelette | B7: =Check!B47 -> 1 | C7: =Check!D47 -> 423.5 | D7: =Check!E47 -> 423.5 | E7: =IF(COUNTIF(Check!G47:G54,"NO")=0,"Yes","NO") -> Yes | F7: Yes | G7: 1 | H7: red / red / green / amber | I7: High protein, Low sugars
A8: Porridge with banana and honey | B8: =Check!B56 -> 2 | C8: =Check!D56 -> 382.9 | D8: =Check!E56 -> 382.9 | E8: =IF(COUNTIF(Check!G56:G63,"NO")=0,"Yes","NO") -> Yes | F8: Yes | G8: 1 | H8: green / green / red / green | I8: Source of protein, Low fat, Low saturated fat, Low salt
A9: Paneer tikka wraps | B9: =Check!B65 -> 2 | C9: =Check!D65 -> 615.675 | D9: =Check!E65 -> 615.68 | E9: =IF(COUNTIF(Check!G65:G72,"NO")=0,"Yes","NO") -> Yes | F9: Yes | G9: 1 | H9: red / red / green / amber | I9: High protein, Low sugars
A10: Tuna pasta bake | B10: =Check!B74 -> 4 | C10: =Check!D74 -> 731.3 | D10: =Check!E74 -> 731.3 | E10: =IF(COUNTIF(Check!G74:G81,"NO")=0,"Yes","NO") -> Yes | F10: Yes | G10: 1 | H10: red / red / green / amber | I10: High protein, Low sugars
A11: Banana and chocolate pancakes (treat) | B11: =Check!B83 -> 2 | C11: =Check!D83 -> 618.3 | D11: =Check!E83 -> 618.3 | E11: =IF(COUNTIF(Check!G83:G90,"NO")=0,"Yes","NO") -> Yes | F11: Yes | G11: 1 | H11: red / red / red / green | I11: Low salt
A13: Recipes passing | E13: =COUNTIF(E2:E11,"Yes")&" of 10" -> 10 of 10 | F13: =COUNTIF(F2:F11,"Yes")&" of 10" -> 10 of 10

Sheet CoFID
A1: Food code | B1: CoFID name | C1: Energy (kcal) | D1: Protein (g) | E1: Fat (g) | F1: Saturates (g) | G1: Carbohydrate (g) | H1: Sugars (g) | I1: Fibre (g) | J1: Salt (g)
A2: 11-716 | B2: Pasta, white, dried, raw | C2: 343 | D2: 11.3 | E2: 1.6 | F2: 0.23 | G2: 75.6 | H2: 2.1 | I2: 3.7 | J2: 0.005
A3: 11-788 | B3: Porridge oats, unfortified | C3: 381 | D3: 10.9 | E3: 8.1 | F3: 1.28 | G3: 70.7 | H3: 0.3 | I3: 7.8 | J3: 0.003
A4: 11-857 | B4: Rice, white, basmati, raw | C4: 351 | D4: 8.1 | E4: 0.5 | F4: 0.14 | G4: 83.7 | H4: 0.1 | I4: 1.1 | J4: 0.003
A5: 11-861 | B5: Rice, white, long grain, raw | C5: 355 | D5: 6.7 | E5: 1 | F5: 0.25 | G5: 85.1 | H5: 0.2 | I5: 1.1 | J5: 0.003
A6: 11-886 | B6: Flour, wheat, white, plain, soft | C6: 352 | D6: 9.1 | E6: 1.4 | F6: 0.44 | G6: 80.9 | H6: 0.6 | I6: 4 | J6: 0.005
A7: 11-925 | B7: Tortilla, wheat, soft | C7: 285 | D7: 7.8 | E7: 5.7 | F7: 2.5 | G7: 53.9 | H7: 2 | I7: 3.6 | J7: 1.555
A8: 12-184 | B8: Yogurt, whole milk, plain | C8: 79 | D8: 5.7 | E8: 3 | F8: 1.91 | G8: 7.8 | H8: 7.8 | I8: 0 | J8: 0.2
A9: 12-313 | B9: Milk, semi-skimmed, pasteurised, average | C9: 46 | D9: 3.5 | E9: 1.7 | F9: 1.07 | G9: 4.7 | H9: 4.7 | I9: 0 | J9: 0.107
A10: 12-346 | B10: Cheese, Cheddar, English | C10: 416 | D10: 25.4 | E10: 34.9 | F10: 21.68 | G10: 0.1 | H10: 0.1 | I10: 0 | J10: 1.808
A11: 12-495 | B11: Cheese, Paneer | C11: 328 | D11: 26 | E11: 24.5 | F11: 15.43 | G11: 0.9 | H11: 0.9 | I11: 0 | J11: 0.048
A12: 12-526 | B12: Cheese, Parmesan, fresh | C12: 415 | D12: 36.2 | E12: 29.7 | F12: 19.25 | G12: 0.9 | H12: 0.9 | I12: 0 | J12: 1.65
A13: 12-937 | B13: Eggs, chicken, whole, raw | C13: 131 | D13: 12.6 | E13: 9 | F13: 2.52 | G13: 0 | H13: 0 | I13: 0 | J13: 0.385
... A28: 13-670 | B28: Beans, chick peas, canned, re-heated, drained | C28: 129 | D28: 8.4 | E28: 3 | F28: 0.29 | G28: 18.3 | H28: 0.7 | I28: 7.1 | J28: 0.003
A29: 13-829 | B29: Garam masala | C29: 379 | D29: 15.6 | E29: 15.1 | G29: 45.2 | J29: 0.242
A30: 13-861 | B30: Turmeric, ground | D30: 6.7 | E30: 7 | F30: 2.9 | J30: 0.077
A31: 13-876 | B31: Curry powder | C31: 233 | D31: 9.5 | E31: 10.8 | G31: 26.1 | I31: 23 | J31: 1.125
A32: 13-889 | B32: Cumin seeds | D32: 17.8 | E32: 22.3 | F32: 1.54 | H32: 2.3 | I32: 10.5 | J32: 0.42
A33: 13-890 | B33: Ginger, fresh | C33: 44 | D33: 1.8 | E33: 0.8 | F33: 0.2 | G33: 8.1 | H33: 1.7 | I33: 2 | J33: 0.033
A34: 14-277 | B34: Lemon juice, fresh | C34: 7 | D34: 0.3 | E34: 0 | F34: 0 | G34: 1.6 | H34: 1.6 | I34: 0.1 | J34: 0.003
A35: 14-318 | B35: Bananas, flesh only | C35: 81 | D35: 1.2 | E35: 0.1 | F35: 0.04 | G35: 20.3 | H35: 18.1 | I35: 1.4 | J35: 0
A36: 14-889 | B36: Coconut milk, retail | C36: 169 | D36: 1.1 | E36: 16.9 | F36: 14.64 | G36: 3.3 | H36: 2 | I36: 0.4 | J36: 0
A37: 16-356 | B37: Salmon, farmed, flesh only, raw | C37: 217 | D37: 20.4 | E37: 15 | F37: 2.77 | G37: 0 | H37: 0 | I37: 0.2 | J37: 0.107
A38: 16-416 | B38: Tuna, canned in brine, drained | C38: 109 | D38: 24.9 | E38: 1 | F38: 0.3 | G38: 0 | H38: 0 | I38: 0 | J38: 0.733
A39: 17-038 | B39: Oil, olive | C39: 899 | D39: 0 | E39: 99.9 | F39: 14.3 | G39: 0 | H39: 0 | I39: 0 | J39: 0
A40: 17-050 | B40: Honey | C40: 288 | D40: 0.4 | E40: 0 | F40: 0 | G40: 76.4 | H40: 76.4 | I40: 0 | J40: 0.028
A41: 17-063 | B41: Sugar, white | C41: 394 | D41: 0 | E41: 0 | F41: 0 | G41: 105 | H41: 105 | I41: 0 | J41: 0.013
A42: 17-367 | B42: Salt | C42: 0 | D42: 0 | E42: 0 | F42: 0 | G42: 0 | H42: 0 | I42: 0 | J42: 98.25
A43: 17-377 | B43: Water, distilled | C43: 0 | D43: 0 | E43: 0 | F43: 0 | G43: 0 | H43: 0 | I43: 0 | J43: 0
A44: 17-491 | B44: Chocolate, plain | C44: 510 | D44: 5 | E44: 28 | F44: 16.8 | G44: 63.5 | H44: 62.6 | I44: 2.5 | J44: 0.015
... A49: 18-469 | B49: Beef, mince, raw | C49: 225 | D49: 19.7 | E49: 16.2 | F49: 6.94 | G49: 0 | H49: 0 | I49: 0 | J49: 0.2

Sheet Recipes
A1: Recipe | B1: Servings | C1: Ingredient (as written) | D1: Grams | E1: Food code | F1: CoFID name | G1: Energy (kcal) | H1: Protein (g) | I1: Fat (g) | J1: Saturates (g) | K1: Carbohydrate (g) | L1: Sugars (g) | M1: Fibre (g) | N1: Salt (g)
A2: Garlic chicken and spinach rice bowl | B2: 2 | C2: chicken breast | D2: 300 | E2: 18-290 | F2: =INDEX(CoFID!$B$2:$B$49,MATCH(E2,CoFID!$A$2:$A$49,0)) -> Chicken, light meat, raw | G2: =D2/100*N(INDEX(CoFID!$C$2:$C$49,MATCH(E2,CoFID!$A$2:$A$49,0))) -> 318 | H2: =D2/100*N(INDEX(CoFID!$D$2:$D$49,MATCH(E2,CoFID!$A$2:$A$49,0))) -> 72 | I2: =D2/100*N(INDEX(CoFID!$E$2:$E$49,MATCH(E2,CoFID!$A$2:$A$49,0))) -> 3.3 | J2: =D2/100*N(INDEX(CoFID!$F$2:$F$49,MATCH(E2,CoFID!$A$2:$A$49,0))) -> 0.9 | K2: =D2/100*N(INDEX(CoFID!$G$2:$G$49,MATCH(E2,CoFID!$A$2:$A$49,0))) -> 0 | L2: =D2/100*N(INDEX(CoFID!$H$2:$H$49,MATCH(E2,CoFID!$A$2:$A$49,0))) -> 0 | M2: =D2/100*N(INDEX(CoFID!$I$2:$I$49,MATCH(E2,CoFID!$A$2:$A$49,0))) -> 0 | N2: =D2/100*N(INDEX(CoFID!$J$2:$J$49,MATCH(E2,CoFID!$A$2:$A$49,0))) -> 0.45
A3: Garlic chicken and spinach rice bowl | B3: 2 | C3: basmati rice | D3: 200 | E3: 11-857 | F3: =INDEX(CoFID!$B$2:$B$49,MATCH(E3,CoFID!$A$2:$A$49,0)) -> Rice, white, basmati, raw | G3: =D3/100*N(INDEX(CoFID!$C$2:$C$49,MATCH(E3,CoFID!$A$2:$A$49,0))) -> 702 | H3: =D3/100*N(INDEX(CoFID!$D$2:$D$49,MATCH(E3,CoFID!$A$2:$A$49,0))) -> 16.2 | I3: =D3/100*N(INDEX(CoFID!$E$2:$E$49,MATCH(E3,CoFID!$A$2:$A$49,0))) -> 1 | J3: =D3/100*N(INDEX(CoFID!$F$2:$F$49,MATCH(E3,CoFID!$A$2:$A$49,0))) -> 0.28 | K3: =D3/100*N(INDEX(CoFID!$G$2:$G$49,MATCH(E3,CoFID!$A$2:$A$49,0))) -> 167.4 | L3: =D3/100*N(INDEX(CoFID!$H$2:$H$49,MATCH(E3,CoFID!$A$2:$A$49,0))) -> 0.2 | M3: =D3/100*N(INDEX(CoFID!$I$2:$I$49,MATCH(E3,CoFID!$A$2:$A$49,0))) -> 2.2 | N3: =D3/100*N(INDEX(CoFID!$J$2:$J$49,MATCH(E3,CoFID!$A$2:$A$49,0))) -> 0.006
A4: Garlic chicken and spinach rice bowl | B4: 2 | C4: spinach | D4: 100 | E4: 13-572 | F4: =INDEX(CoFID!$B$2:$B$49,MATCH(E4,CoFID!$A$2:$A$49,0)) -> Spinach, mature, raw | G4: =D4/100*N(INDEX(CoFID!$C$2:$C$49,MATCH(E4,CoFID!$A$2:$A$49,0))) -> 25 | H4: =D4/100*N(INDEX(CoFID!$D$2:$D$49,MATCH(E4,CoFID!$A$2:$A$49,0))) -> 2.8 | I4: =D4/100*N(INDEX(CoFID!$E$2:$E$49,MATCH(E4,CoFID!$A$2:$A$49,0))) -> 0.8 | J4: =D4/100*N(INDEX(CoFID!$F$2:$F$49,MATCH(E4,CoFID!$A$2:$A$49,0))) -> 0.1 | K4: =D4/100*N(INDEX(CoFID!$G$2:$G$49,MATCH(E4,CoFID!$A$2:$A$49,0))) -> 1.6 | L4: =D4/100*N(INDEX(CoFID!$H$2:$H$49,MATCH(E4,CoFID!$A$2:$A$49,0))) -> 1.5 | M4: =D4/100*N(INDEX(CoFID!$I$2:$I$49,MATCH(E4,CoFID!$A$2:$A$49,0))) -> 2.1 | N4: =D4/100*N(INDEX(CoFID!$J$2:$J$49,MATCH(E4,CoFID!$A$2:$A$49,0))) -> 0.35
A5: Garlic chicken and spinach rice bowl | B5: 2 | C5: garlic | D5: 15 | E5: 13-244 | F5: =INDEX(CoFID!$B$2:$B$49,MATCH(E5,CoFID!$A$2:$A$49,0)) -> Garlic, raw | G5: =D5/100*N(INDEX(CoFID!$C$2:$C$49,MATCH(E5,CoFID!$A$2:$A$49,0))) -> 14.7 | H5: =D5/100*N(INDEX(CoFID!$D$2:$D$49,MATCH(E5,CoFID!$A$2:$A$49,0))) -> 1.185 | I5: =D5/100*N(INDEX(CoFID!$E$2:$E$49,MATCH(E5,CoFID!$A$2:$A$49,0))) -> 0.09 | J5: =D5/100*N(INDEX(CoFID!$F$2:$F$49,MATCH(E5,CoFID!$A$2:$A$49,0))) -> 0.015 | K5: =D5/100*N(INDEX(CoFID!$G$2:$G$49,MATCH(E5,CoFID!$A$2:$A$49,0))) -> 2.445 | L5: =D5/100*N(INDEX(CoFID!$H$2:$H$49,MATCH(E5,CoFID!$A$2:$A$49,0))) -> 0.24 | M5: =D5/100*N(INDEX(CoFID!$I$2:$I$49,MATCH(E5,CoFID!$A$2:$A$49,0))) -> 0.615 | N5: =D5/100*N(INDEX(CoFID!$J$2:$J$49,MATCH(E5,CoFID!$A$2:$A$49,0))) -> 0.0015
A6: Garlic chicken and spinach rice bowl | B6: 2 | C6: olive oil | D6: 15 | E6: 17-038 | F6: =INDEX(CoFID!$B$2:$B$49,MATCH(E6,CoFID!$A$2:$A$49,0)) -> Oil, olive | G6: =D6/100*N(INDEX(CoFID!$C$2:$C$49,MATCH(E6,CoFID!$A$2:$A$49,0))) -> 134.85 | H6: =D6/100*N(INDEX(CoFID!$D$2:$D$49,MATCH(E6,CoFID!$A$2:$A$49,0))) -> 0 | I6: =D6/100*N(INDEX(CoFID!$E$2:$E$49,MATCH(E6,CoFID!$A$2:$A$49,0))) -> 14.985 | J6: =D6/100*N(INDEX(CoFID!$F$2:$F$49,MATCH(E6,CoFID!$A$2:$A$49,0))) -> 2.145 | K6: =D6/100*N(INDEX(CoFID!$G$2:$G$49,MATCH(E6,CoFID!$A$2:$A$49,0))) -> 0 | L6: =D6/100*N(INDEX(CoFID!$H$2:$H$49,MATCH(E6,CoFID!$A$2:$A$49,0))) -> 0 | M6: =D6/100*N(INDEX(CoFID!$I$2:$I$49,MATCH(E6,CoFID!$A$2:$A$49,0))) -> 0 | N6: =D6/100*N(INDEX(CoFID!$J$2:$J$49,MATCH(E6,CoFID!$A$2:$A$49,0))) -> 0
A7: Garlic chicken and spinach rice bowl | B7: 2 | C7: garam masala | D7: 5 | E7: 13-829 | F7: =INDEX(CoFID!$B$2:$B$49,MATCH(E7,CoFID!$A$2:$A$49,0)) -> Garam masala | G7: =D7/100*N(INDEX(CoFID!$C$2:$C$49,MATCH(E7,CoFID!$A$2:$A$49,0))) -> 18.95 | H7: =D7/100*N(INDEX(CoFID!$D$2:$D$49,MATCH(E7,CoFID!$A$2:$A$49,0))) -> 0.78 | I7: =D7/100*N(INDEX(CoFID!$E$2:$E$49,MATCH(E7,CoFID!$A$2:$A$49,0))) -> 0.755 | J7: =D7/100*N(INDEX(CoFID!$F$2:$F$49,MATCH(E7,CoFID!$A$2:$A$49,0))) -> 0 | K7: =D7/100*N(INDEX(CoFID!$G$2:$G$49,MATCH(E7,CoFID!$A$2:$A$49,0))) -> 2.26 | L7: =D7/100*N(INDEX(CoFID!$H$2:$H$49,MATCH(E7,CoFID!$A$2:$A$49,0))) -> 0 | M7: =D7/100*N(INDEX(CoFID!$I$2:$I$49,MATCH(E7,CoFID!$A$2:$A$49,0))) -> 0 | N7: =D7/100*N(INDEX(CoFID!$J$2:$J$49,MATCH(E7,CoFID!$A$2:$A$49,0))) -> 0.0121
A8: Garlic chicken and spinach rice bowl | B8: 2 | C8: salt | D8: 2 | E8: 17-367 | F8: =INDEX(CoFID!$B$2:$B$49,MATCH(E8,CoFID!$A$2:$A$49,0)) -> Salt | G8: =D8/100*N(INDEX(CoFID!$C$2:$C$49,MATCH(E8,CoFID!$A$2:$A$49,0))) -> 0 | H8: =D8/100*N(INDEX(CoFID!$D$2:$D$49,MATCH(E8,CoFID!$A$2:$A$49,0))) -> 0 | I8: =D8/100*N(INDEX(CoFID!$E$2:$E$49,MATCH(E8,CoFID!$A$2:$A$49,0))) -> 0 | J8: =D8/100*N(INDEX(CoFID!$F$2:$F$49,MATCH(E8,CoFID!$A$2:$A$49,0))) -> 0 | K8: =D8/100*N(INDEX(CoFID!$G$2:$G$49,MATCH(E8,CoFID!$A$2:$A$49,0))) -> 0 | L8: =D8/100*N(INDEX(CoFID!$H$2:$H$49,MATCH(E8,CoFID!$A$2:$A$49,0))) -> 0 | M8: =D8/100*N(INDEX(CoFID!$I$2:$I$49,MATCH(E8,CoFID!$A$2:$A$49,0))) -> 0 | N8: =D8/100*N(INDEX(CoFID!$J$2:$J$49,MATCH(E8,CoFID!$A$2:$A$49,0))) -> 1.965
A9: Spaghetti bolognese | B9: 4 | C9: beef mince | D9: 500 | E9: 18-469 | F9: =INDEX(CoFID!$B$2:$B$49,MATCH(E9,CoFID!$A$2:$A$49,0)) -> Beef, mince, raw | G9: =D9/100*N(INDEX(CoFID!$C$2:$C$49,MATCH(E9,CoFID!$A$2:$A$49,0))) -> 1125 | H9: =D9/100*N(INDEX(CoFID!$D$2:$D$49,MATCH(E9,CoFID!$A$2:$A$49,0))) -> 98.5 | I9: =D9/100*N(INDEX(CoFID!$E$2:$E$49,MATCH(E9,CoFID!$A$2:$A$49,0))) -> 81 | J9: =D9/100*N(INDEX(CoFID!$F$2:$F$49,MATCH(E9,CoFID!$A$2:$A$49,0))) -> 34.7 | K9: =D9/100*N(INDEX(CoFID!$G$2:$G$49,MATCH(E9,CoFID!$A$2:$A$49,0))) -> 0 | L9: =D9/100*N(INDEX(CoFID!$H$2:$H$49,MATCH(E9,CoFID!$A$2:$A$49,0))) -> 0 | M9: =D9/100*N(INDEX(CoFID!$I$2:$I$49,MATCH(E9,CoFID!$A$2:$A$49,0))) -> 0 | N9: =D9/100*N(INDEX(CoFID!$J$2:$J$49,MATCH(E9,CoFID!$A$2:$A$49,0))) -> 1
A10: Spaghetti bolognese | B10: 4 | C10: spaghetti | D10: 400 | E10: 11-716 | F10: =INDEX(CoFID!$B$2:$B$49,MATCH(E10,CoFID!$A$2:$A$49,0)) -> Pasta, white, dried, raw | G10: =D10/100*N(INDEX(CoFID!$C$2:$C$49,MATCH(E10,CoFID!$A$2:$A$49,0))) -> 1372 | H10: =D10/100*N(INDEX(CoFID!$D$2:$D$49,MATCH(E10,CoFID!$A$2:$A$49,0))) -> 45.2 | I10: =D10/100*N(INDEX(CoFID!$E$2:$E$49,MATCH(E10,CoFID!$A$2:$A$49,0))) -> 6.4 | J10: =D10/100*N(INDEX(CoFID!$F$2:$F$49,MATCH(E10,CoFID!$A$2:$A$49,0))) -> 0.92 | K10: =D10/100*N(INDEX(CoFID!$G$2:$G$49,MATCH(E10,CoFID!$A$2:$A$49,0))) -> 302.4 | L10: =D10/100*N(INDEX(CoFID!$H$2:$H$49,MATCH(E10,CoFID!$A$2:$A$49,0))) -> 8.4 | M10: =D10/100*N(INDEX(CoFID!$I$2:$I$49,MATCH(E10,CoFID!$A$2:$A$49,0))) -> 14.8 | N10: =D10/100*N(INDEX(CoFID!$J$2:$J$49,MATCH(E10,CoFID!$A$2:$A$49,0))) -> 0.02
A11: Spaghetti bolognese | B11: 4 | C11: chopped tomatoes | D11: 400 | E11: 13-530 | F11: =INDEX(CoFID!$B$2:$B$49,MATCH(E11,CoFID!$A$2:$A$49,0)) -> Tomatoes, canned, whole contents | G11: =D11/100*N(INDEX(CoFID!$C$2:$C$49,MATCH(E11,CoFID!$A$2:$A$49,0))) -> 76 | H11: =D11/100*N(INDEX(CoFID!$D$2:$D$49,MATCH(E11,CoFID!$A$2:$A$49,0))) -> 4.4 | I11: =D11/100*N(INDEX(CoFID!$E$2:$E$49,MATCH(E11,CoFID!$A$2:$A$49,0))) -> 0.4 | J11: =D11/100*N(INDEX(CoFID!$F$2:$F$49,MATCH(E11,CoFID!$A$2:$A$49,0))) -> 0.04 | K11: =D11/100*N(INDEX(CoFID!$G$2:$G$49,MATCH(E11,CoFID!$A$2:$A$49,0))) -> 15.2 | L11: =D11/100*N(INDEX(CoFID!$H$2:$H$49,MATCH(E11,CoFID!$A$2:$A$49,0))) -> 15.2 | M11: =D11/100*N(INDEX(CoFID!$I$2:$I$49,MATCH(E11,CoFID!$A$2:$A$49,0))) -> 3.2 | N11: =D11/100*N(INDEX(CoFID!$J$2:$J$49,MATCH(E11,CoFID!$A$2:$A$49,0))) -> 0.052
A12: Spaghetti bolognese | B12: 4 | C12: onion | D12: 150 | E12: 13-499 | F12: =INDEX(CoFID!$B$2:$B$49,MATCH(E12,CoFID!$A$2:$A$49,0)) -> Onions, raw | G12: =D12/100*N(INDEX(CoFID!$C$2:$C$49,MATCH(E12,CoFID!$A$2:$A$49,0))) -> 52.5 | H12: =D12/100*N(INDEX(CoFID!$D$2:$D$49,MATCH(E12,CoFID!$A$2:$A$49,0))) -> 1.5 | I12: =D12/100*N(INDEX(CoFID!$E$2:$E$49,MATCH(E12,CoFID!$A$2:$A$49,0))) -> 0.15 | J12: =D12/100*N(INDEX(CoFID!$F$2:$F$49,MATCH(E12,CoFID!$A$2:$A$49,0))) -> 0 | K12: =D12/100*N(INDEX(CoFID!$G$2:$G$49,MATCH(E12,CoFID!$A$2:$A$49,0))) -> 12 | L12: =D12/100*N(INDEX(CoFID!$H$2:$H$49,MATCH(E12,CoFID!$A$2:$A$49,0))) -> 9.3 | M12: =D12/100*N(INDEX(CoFID!$I$2:$I$49,MATCH(E12,CoFID!$A$2:$A$49,0))) -> 3.3 | N12: =D12/100*N(INDEX(CoFID!$J$2:$J$49,MATCH(E12,CoFID!$A$2:$A$49,0))) -> 0.0105
A13: Spaghetti bolognese | B13: 4 | C13: carrot | D13: 100 | E13: 13-496 | F13: =INDEX(CoFID!$B$2:$B$49,MATCH(E13,CoFID!$A$2:$A$49,0)) -> Carrots, old, raw | G13: =D13/100*N(INDEX(CoFID!$C$2:$C$49,MATCH(E13,CoFID!$A$2:$A$49,0))) -> 34 | H13: =D13/100*N(INDEX(CoFID!$D$2:$D$49,MATCH(E13,CoFID!$A$2:$A$49,0))) -> 0.5 | I13: =D13/100*N(INDEX(CoFID!$E$2:$E$49,MATCH(E13,CoFID!$A$2:$A$49,0))) -> 0.4 | J13: =D13/100*N(INDEX(CoFID!$F$2:$F$49,MATCH(E13,CoFID!$A$2:$A$49,0))) -> 0.1 | K13: =D13/100*N(INDEX(CoFID!$G$2:$G$49,MATCH(E13,CoFID!$A$2:$A$49,0))) -> 7.7 | L13: =D13/100*N(INDEX(CoFID!$H$2:$H$49,MATCH(E13,CoFID!$A$2:$A$49,0))) -> 7.2 | M13: =D13/100*N(INDEX(CoFID!$I$2:$I$49,MATCH(E13,CoFID!$A$2:$A$49,0))) -> 3.9 | N13: =D13/100*N(INDEX(CoFID!$J$2:$J$49,MATCH(E13,CoFID!$A$2:$A$49,0))) -> 0.068
... A72: Banana and chocolate pancakes (treat) | B72: 2 | C72: butter | D72: 20 | E72: 17-685 | F72: =INDEX(CoFID!$B$2:$B$49,MATCH(E72,CoFID!$A$2:$A$49,0)) -> Butter, salted | G72: =D72/100*N(INDEX(CoFID!$C$2:$C$49,MATCH(E72,CoFID!$A$2:$A$49,0))) -> 148.8 | H72: =D72/100*N(INDEX(CoFID!$D$2:$D$49,MATCH(E72,CoFID!$A$2:$A$49,0))) -> 0.12 | I72: =D72/100*N(INDEX(CoFID!$E$2:$E$49,MATCH(E72,CoFID!$A$2:$A$49,0))) -> 16.44 | J72: =D72/100*N(INDEX(CoFID!$F$2:$F$49,MATCH(E72,CoFID!$A$2:$A$49,0))) -> 10.418 | K72: =D72/100*N(INDEX(CoFID!$G$2:$G$49,MATCH(E72,CoFID!$A$2:$A$49,0))) -> 0.12 | L72: =D72/100*N(INDEX(CoFID!$H$2:$H$49,MATCH(E72,CoFID!$A$2:$A$49,0))) -> 0.12 | M72: =D72/100*N(INDEX(CoFID!$I$2:$I$49,MATCH(E72,CoFID!$A$2:$A$49,0))) -> 0 | N72: =D72/100*N(INDEX(CoFID!$J$2:$J$49,MATCH(E72,CoFID!$A$2:$A$49,0))) -> 0.365

Sheet Check
A1: Recipe | B1: Servings | C1: Nutrient | D1: Spreadsheet per serving | E1: Engine per serving | F1: Difference | G1: Agrees?
A2: Garlic chicken and spinach rice bowl | B2: 2 | C2: Energy (kcal) | D2: =SUMIFS(Recipes!$G$2:$G$72,Recipes!$A$2:$A$72,A2)/B2 -> 606.75 | E2: 606.75 | F2: =E2-D2 -> 0 | G2: =IF(ABS(F2)<=MAX(0.05,ABS(D2)*0.005),"Yes","NO") -> Yes
A3: Garlic chicken and spinach rice bowl | B3: 2 | C3: Protein (g) | D3: =SUMIFS(Recipes!$H$2:$H$72,Recipes!$A$2:$A$72,A3)/B3 -> 46.4825 | E3: 46.48 | F3: =E3-D3 -> -0.0025 | G3: =IF(ABS(F3)<=MAX(0.05,ABS(D3)*0.005),"Yes","NO") -> Yes
A4: Garlic chicken and spinach rice bowl | B4: 2 | C4: Fat (g) | D4: =SUMIFS(Recipes!$I$2:$I$72,Recipes!$A$2:$A$72,A4)/B4 -> 10.465 | E4: 10.46 | F4: =E4-D4 -> -0.005 | G4: =IF(ABS(F4)<=MAX(0.05,ABS(D4)*0.005),"Yes","NO") -> Yes
A5: Garlic chicken and spinach rice bowl | B5: 2 | C5: Saturates (g) | D5: =SUMIFS(Recipes!$J$2:$J$72,Recipes!$A$2:$A$72,A5)/B5 -> 1.72 | E5: 1.72 | F5: =E5-D5 -> 0 | G5: =IF(ABS(F5)<=MAX(0.05,ABS(D5)*0.005),"Yes","NO") -> Yes
A6: Garlic chicken and spinach rice bowl | B6: 2 | C6: Carbohydrate (g) | D6: =SUMIFS(Recipes!$K$2:$K$72,Recipes!$A$2:$A$72,A6)/B6 -> 86.8525 | E6: 86.85 | F6: =E6-D6 -> -0.0025 | G6: =IF(ABS(F6)<=MAX(0.05,ABS(D6)*0.005),"Yes","NO") -> Yes
A7: Garlic chicken and spinach rice bowl | B7: 2 | C7: Sugars (g) | D7: =SUMIFS(Recipes!$L$2:$L$72,Recipes!$A$2:$A$72,A7)/B7 -> 0.97 | E7: 0.97 | F7: =E7-D7 -> 0 | G7: =IF(ABS(F7)<=MAX(0.05,ABS(D7)*0.005),"Yes","NO") -> Yes
A8: Garlic chicken and spinach rice bowl | B8: 2 | C8: Fibre (g) | D8: =SUMIFS(Recipes!$M$2:$M$72,Recipes!$A$2:$A$72,A8)/B8 -> 2.4575 | E8: 2.46 | F8: =E8-D8 -> 0.0025 | G8: =IF(ABS(F8)<=MAX(0.05,ABS(D8)*0.005),"Yes","NO") -> Yes
A9: Garlic chicken and spinach rice bowl | B9: 2 | C9: Salt (g) | D9: =SUMIFS(Recipes!$N$2:$N$72,Recipes!$A$2:$A$72,A9)/B9 -> 1.3923 | E9: 1.39 | F9: =E9-D9 -> -0.0023 | G9: =IF(ABS(F9)<=MAX(0.05,ABS(D9)*0.005),"Yes","NO") -> Yes
A11: Spaghetti bolognese | B11: 4 | C11: Energy (kcal) | D11: =SUMIFS(Recipes!$G$2:$G$72,Recipes!$A$2:$A$72,A11)/B11 -> 737.1875 | E11: 737.19 | F11: =E11-D11 -> 0.0025 | G11: =IF(ABS(F11)<=MAX(0.05,ABS(D11)*0.005),"Yes","NO") -> Yes
A12: Spaghetti bolognese | B12: 4 | C12: Protein (g) | D12: =SUMIFS(Recipes!$H$2:$H$72,Recipes!$A$2:$A$72,A12)/B12 -> 40.7675 | E12: 40.77 | F12: =E12-D12 -> 0.0025 | G12: =IF(ABS(F12)<=MAX(0.05,ABS(D12)*0.005),"Yes","NO") -> Yes
A13: Spaghetti bolognese | B13: 4 | C13: Fat (g) | D13: =SUMIFS(Recipes!$I$2:$I$72,Recipes!$A$2:$A$72,A13)/B13 -> 28.09125 | E13: 28.09 | F13: =E13-D13 -> -0.00125 | G13: =IF(ABS(F13)<=MAX(0.05,ABS(D13)*0.005),"Yes","NO") -> Yes
A14: Spaghetti bolognese | B14: 4 | C14: Saturates (g) | D14: =SUMIFS(Recipes!$J$2:$J$72,Recipes!$A$2:$A$72,A14)/B14 -> 10.9255 | E14: 10.93 | F14: =E14-D14 -> 0.0045 | G14: =IF(ABS(F14)<=MAX(0.05,ABS(D14)*0.005),"Yes","NO") -> Yes
A15: Spaghetti bolognese | B15: 4 | C15: Carbohydrate (g) | D15: =SUMIFS(Recipes!$K$2:$K$72,Recipes!$A$2:$A$72,A15)/B15 -> 85.7675 | E15: 85.77 | F15: =E15-D15 -> 0.0025 | G15: =IF(ABS(F15)<=MAX(0.05,ABS(D15)*0.005),"Yes","NO") -> Yes
A16: Spaghetti bolognese | B16: 4 | C16: Sugars (g) | D16: =SUMIFS(Recipes!$L$2:$L$72,Recipes!$A$2:$A$72,A16)/B16 -> 11.1 | E16: 11.1 | F16: =E16-D16 -> 0 | G16: =IF(ABS(F16)<=MAX(0.05,ABS(D16)*0.005),"Yes","NO") -> Yes
A17: Spaghetti bolognese | B17: 4 | C17: Fibre (g) | D17: =SUMIFS(Recipes!$M$2:$M$72,Recipes!$A$2:$A$72,A17)/B17 -> 6.755 | E17: 6.75 | F17: =E17-D17 -> -0.005 | G17: =IF(ABS(F17)<=MAX(0.05,ABS(D17)*0.005),"Yes","NO") -> Yes
A18: Spaghetti bolognese | B18: 4 | C18: Salt (g) | D18: =SUMIFS(Recipes!$N$2:$N$72,Recipes!$A$2:$A$72,A18)/B18 -> 0.420775 | E18: 0.42 | F18: =E18-D18 -> -0.000775 | G18: =IF(ABS(F18)<=MAX(0.05,ABS(D18)*0.005),"Yes","NO") -> Yes
A20: Chickpea and coconut curry with rice | B20: 4 | C20: Energy (kcal) | D20: =SUMIFS(Recipes!$G$2:$G$72,Recipes!$A$2:$A$72,A20)/B20 -> 665.8125 | E20: 665.81 | F20: =E20-D20 -> -0.0025 | G20: =IF(ABS(F20)<=MAX(0.05,ABS(D20)*0.005),"Yes","NO") -> Yes
A21: Chickpea and coconut curry with rice | B21: 4 | C21: Protein (g) | D21: =SUMIFS(Recipes!$H$2:$H$72,Recipes!$A$2:$A$72,A21)/B21 -> 18.1825 | E21: 18.18 | F21: =E21-D21 -> -0.0025 | G21: =IF(ABS(F21)<=MAX(0.05,ABS(D21)*0.005),"Yes","NO") -> Yes
A22: Chickpea and coconut curry with rice | B22: 4 | C22: Fat (g) | D22: =SUMIFS(Recipes!$I$2:$I$72,Recipes!$A$2:$A$72,A22)/B22 -> 25.44875 | E22: 25.45 | F22: =E22-D22 -> 0.00125 | G22: =IF(ABS(F22)<=MAX(0.05,ABS(D22)*0.005),"Yes","NO") -> Yes
A23: Chickpea and coconut curry with rice | B23: 4 | C23: Saturates (g) | D23: =SUMIFS(Recipes!$J$2:$J$72,Recipes!$A$2:$A$72,A23)/B23 -> 15.443 | E23: 15.44 | F23: =E23-D23 -> -0.003 | G23: =IF(ABS(F23)<=MAX(0.05,ABS(D23)*0.005),"Yes","NO") -> Yes
A24: Chickpea and coconut curry with rice | B24: 4 | C24: Carbohydrate (g) | D24: =SUMIFS(Recipes!$K$2:$K$72,Recipes!$A$2:$A$72,A24)/B24 -> 97.24875 | E24: 97.25 | F24: =E24-D24 -> 0.00125 | G24: =IF(ABS(F24)<=MAX(0.05,ABS(D24)*0.005),"Yes","NO") -> Yes
A25: Chickpea and coconut curry with rice | B25: 4 | C25: Sugars (g) | D25: =SUMIFS(Recipes!$L$2:$L$72,Recipes!$A$2:$A$72,A25)/B25 -> 9.21875 | E25: 9.22 | F25: =E25-D25 -> 0.00125 | G25: =IF(ABS(F25)<=MAX(0.05,ABS(D25)*0.005),"Yes","NO") -> Yes
A26: Chickpea and coconut curry with rice | B26: 4 | C26: Fibre (g) | D26: =SUMIFS(Recipes!$M$2:$M$72,Recipes!$A$2:$A$72,A26)/B26 -> 12.1225 | E26: 12.12 | F26: =E26-D26 -> -0.0025 | G26: =IF(ABS(F26)<=MAX(0.05,ABS(D26)*0.005),"Yes","NO") -> Yes
A27: Chickpea and coconut curry with rice | B27: 4 | C27: Salt (g) | D27: =SUMIFS(Recipes!$N$2:$N$72,Recipes!$A$2:$A$72,A27)/B27 -> 0.0510875 | E27: 0.05 | F27: =E27-D27 -> -0.0010875 | G27: =IF(ABS(F27)<=MAX(0.05,ABS(D27)*0.005),"Yes","NO") -> Yes
A29: Salmon, new potatoes and broccoli | B29: 2 | C29: Energy (kcal) | D29: =SUMIFS(Recipes!$G$2:$G$72,Recipes!$A$2:$A$72,A29)/B29 -> 508.6 | E29: 508.6 | F29: =E29-D29 -> 0 | G29: =IF(ABS(F29)<=MAX(0.05,ABS(D29)*0.005),"Yes","NO") -> Yes
A30: Salmon, new potatoes and broccoli | B30: 2 | C30: Protein (g) | D30: =SUMIFS(Recipes!$H$2:$H$72,Recipes!$A$2:$A$72,A30)/B30 -> 34.295 | E30: 34.3 | F30: =E30-D30 -> 0.005 | G30: =IF(ABS(F30)<=MAX(0.05,ABS(D30)*0.005),"Yes","NO") -> Yes
A31: Salmon, new potatoes and broccoli | B31: 2 | C31: Fat (g) | D31: =SUMIFS(Recipes!$I$2:$I$72,Recipes!$A$2:$A$72,A31)/B31 -> 26.465 | E31: 26.46 | F31: =E31-D31 -> -0.005 | G31: =IF(ABS(F31)<=MAX(0.05,ABS(D31)*0.005),"Yes","NO") -> Yes
A32: Salmon, new potatoes and broccoli | B32: 2 | C32: Saturates (g) | D32: =SUMIFS(Recipes!$J$2:$J$72,Recipes!$A$2:$A$72,A32)/B32 -> 7.73775 | E32: 7.74 | F32: =E32-D32 -> 0.00225 | G32: =IF(ABS(F32)<=MAX(0.05,ABS(D32)*0.005),"Yes","NO") -> Yes
A33: Salmon, new potatoes and broccoli | B33: 2 | C33: Carbohydrate (g) | D33: =SUMIFS(Recipes!$K$2:$K$72,Recipes!$A$2:$A$72,A33)/B33 -> 35.605 | E33: 35.61 | F33: =E33-D33 -> 0.005 | G33: =IF(ABS(F33)<=MAX(0.05,ABS(D33)*0.005),"Yes","NO") -> Yes
A34: Salmon, new potatoes and broccoli | B34: 2 | C34: Sugars (g) | D34: =SUMIFS(Recipes!$L$2:$L$72,Recipes!$A$2:$A$72,A34)/B34 -> 4.705 | E34: 4.71 | F34: =E34-D34 -> 0.005 | G34: =IF(ABS(F34)<=MAX(0.05,ABS(D34)*0.005),"Yes","NO") -> Yes
A35: Salmon, new potatoes and broccoli | B35: 2 | C35: Fibre (g) | D35: =SUMIFS(Recipes!$M$2:$M$72,Recipes!$A$2:$A$72,A35)/B35 -> 7.87 | E35: 7.87 | F35: =E35-D35 -> 0 | G35: =IF(ABS(F35)<=MAX(0.05,ABS(D35)*0.005),"Yes","NO") -> Yes
A36: Salmon, new potatoes and broccoli | B36: 2 | C36: Salt (g) | D36: =SUMIFS(Recipes!$N$2:$N$72,Recipes!$A$2:$A$72,A36)/B36 -> 0.312275 | E36: 0.31 | F36: =E36-D36 -> -0.002275 | G36: =IF(ABS(F36)<=MAX(0.05,ABS(D36)*0.005),"Yes","NO") -> Yes
A38: Red lentil dal | B38: 4 | C38: Energy (kcal) | D38: =SUMIFS(Recipes!$G$2:$G$72,Recipes!$A$2:$A$72,A38)/B38 -> 264.45 | E38: 264.45 | F38: =E38-D38 -> 0 | G38: =IF(ABS(F38)<=MAX(0.05,ABS(D38)*0.005),"Yes","NO") -> Yes
A39: Red lentil dal | B39: 4 | C39: Protein (g) | D39: =SUMIFS(Recipes!$H$2:$H$72,Recipes!$A$2:$A$72,A39)/B39 -> 17.47875 | E39: 17.48 | F39: =E39-D39 -> 0.00125 | G39: =IF(ABS(F39)<=MAX(0.05,ABS(D39)*0.005),"Yes","NO") -> Yes
A40: Red lentil dal | B40: 4 | C40: Fat (g) | D40: =SUMIFS(Recipes!$I$2:$I$72,Recipes!$A$2:$A$72,A40)/B40 -> 6.49375 | E40: 6.49 | F40: =E40-D40 -> -0.00375 | G40: =IF(ABS(F40)<=MAX(0.05,ABS(D40)*0.005),"Yes","NO") -> Yes
A41: Red lentil dal | B41: 4 | C41: Saturates (g) | D41: =SUMIFS(Recipes!$J$2:$J$72,Recipes!$A$2:$A$72,A41)/B41 -> 3.164 | E41: 3.16 | F41: =E41-D41 -> -0.004 | G41: =IF(ABS(F41)<=MAX(0.05,ABS(D41)*0.005),"Yes","NO") -> Yes
A42: Red lentil dal | B42: 4 | C42: Carbohydrate (g) | D42: =SUMIFS(Recipes!$K$2:$K$72,Recipes!$A$2:$A$72,A42)/B42 -> 37.51 | E42: 37.51 | F42: =E42-D42 -> 0 | G42: =IF(ABS(F42)<=MAX(0.05,ABS(D42)*0.005),"Yes","NO") -> Yes
A43: Red lentil dal | B43: 4 | C43: Sugars (g) | D43: =SUMIFS(Recipes!$L$2:$L$72,Recipes!$A$2:$A$72,A43)/B43 -> 5.14875 | E43: 5.15 | F43: =E43-D43 -> 0.00125 | G43: =IF(ABS(F43)<=MAX(0.05,ABS(D43)*0.005),"Yes","NO") -> Yes
A44: Red lentil dal | B44: 4 | C44: Fibre (g) | D44: =SUMIFS(Recipes!$M$2:$M$72,Recipes!$A$2:$A$72,A44)/B44 -> 12.38375 | E44: 12.38 | F44: =E44-D44 -> -0.00375 | G44: =IF(ABS(F44)<=MAX(0.05,ABS(D44)*0.005),"Yes","NO") -> Yes
...
