Workbook

Sheet Read me
A1: CulinaAI ingredient prices
A3: What this is | B3: A price per kg for each of the 190 foods CulinaAI's ingredient names map to. It powers the cheapest version of a dish and the cost per serving. 187 of 190 have a price.
A4: Where prices come from | B4: 1. ONS (70 foods, status starts with 'ONS'): ONS average prices for August 2026 (tab 'ONS items used'). Open Government Licence v3.0. 'Stand-in' = ONS has no exact item, so the nearest is used; the note says which.
B5: 2. Shop average (116 foods, 2 of them a stand-in that borrows another food's prices; the note says which): the average of Tesco, Sainsbury's and Morrisons shelf prices read on 2 Oct 2026. Own-brand standard range where sold, smallest normal pack, regular price (no Clubcard or Nectar prices). At least 2 shops per food. Every shop price is in the 'Shop prices' tab.
B6: These three shops hold about half the GB grocery market (51.6%, Kantar, 12 weeks to July 2026). Asda and Aldi block automated reading of their sites and Lidl shows few prices online, so they are not included.
B7: 3. Tinned foods (beans, chickpeas, tuna, sweetcorn, sardines) are priced per kg of DRAINED weight, because the nutrition data is for the drained food.
B8: 4. Loose items sold 'each' (peppers, cabbage, avocado...) use the USDA FoodData Central weight of one item. For mango, avocado and orange that is the weight of the flesh, so the price is per kg of flesh. Eggs: 12 x 58 g, the middle of the UK medium egg band.
A9: Known differences | B9: ONS averages include branded products and convenience stores. For the ten foods sold 'each' that both cover, ONS was 4% to 46% higher than the three shops, and 137% higher for peppers (ONS £1.66 vs 70p each). See docs/evaluation/ons_vs_shop_each_items.csv.
B10: Shelf prices change weekly. Show costs as estimates, e.g. 'Estimated cost, from ONS average prices (August 2026) and Tesco, Sainsbury's and Morrisons prices (October 2026). Prices vary by shop and over time.'
A11: Still blank (red) | B11: Beetroot, butternut squash and garlic: see each row's note. Fill the yellow cells if you find a price.
A12: Checking a row | B12: Filter the 'Shop prices' tab by food code. Notes marked DOUBTFUL explain a judgement call.
A14: Progress
A15: Foods in the sheet | B15: =COUNTA(Prices!A3:A192) -> 190
A16: With a price per kg | B16: =COUNT(Prices!I3:I192) -> 187
A17: Shop averages | B17: =COUNTIF(Prices!D3:D192,"Shop*") -> 116
A18: From ONS | B18: =COUNTIF(Prices!D3:D192,"ONS*") -> 70
A19: Still blank | B19: =COUNTIF(Prices!D3:D192,"No price yet") -> 3

Sheet Prices
A1: Food code | B1: CoFID food | C1: Recipe names | D1: Status | E1: Price source | F1: Product / ONS item | G1: Pack price (£) | H1: Pack weight (g) | I1: Price per kg (£) | J1: Shop | K1: Date checked | L1: Notes
A2: (example) | B2: Lentils, red, split, dried, raw | C2: red lentil; lentil | D2: Example | E2: Supermarket shelf price | F2: Own-brand red split lentils 500 g | G2: 1.1 | H2: 500 | I2: =IF(AND(ISNUMBER(G2),ISNUMBER(H2),H2>0),G2/H2*1000,"") -> 2.2 | J2: Tesco | K2: 05/10/2026 | L2: Example only, not a real price. Delete or ignore this row.
A3: 11-861 | B3: Rice, white, long grain, raw | C3: rice; white rice; long grain rice | D3: Shop average | E3: Average of 3 supermarkets, 2 Oct 2026 | F3: Own-brand standard range where sold (see 'Shop prices' tab) | G3: 1.52 | H3: 1000 | I3: =IF(AND(ISNUMBER(G3),ISNUMBER(H3),H3>0),G3/H3*1000,"") -> 1.52 | J3: Morrisons, Sainsbury's, Tesco | K3: 02/10/2026 | L3: Range £1.25 to £2.00 per kg
A4: 11-868 | B4: Rice, brown, wholegrain, raw | C4: brown rice | D4: Shop average | E4: Average of 3 supermarkets, 2 Oct 2026 | F4: Own-brand standard range where sold (see 'Shop prices' tab) | G4: 1.39 | H4: 1000 | I4: =IF(AND(ISNUMBER(G4),ISNUMBER(H4),H4>0),G4/H4*1000,"") -> 1.39 | J4: Morrisons, Sainsbury's, Tesco | K4: 02/10/2026 | L4: Range £1.38 to £1.39 per kg
A5: 11-878 | B5: Rice, white, Italian Arborio risotto, raw | C5: arborio rice | D5: Shop average | E5: Average of 3 supermarkets, 2 Oct 2026 | F5: Own-brand standard range where sold (see 'Shop prices' tab) | G5: 4.6 | H5: 1000 | I5: =IF(AND(ISNUMBER(G5),ISNUMBER(H5),H5>0),G5/H5*1000,"") -> 4.6 | J5: Morrisons, Sainsbury's, Tesco | K5: 02/10/2026 | L5: Range £3.30 to £6.00 per kg
A6: 11-889 | B6: Flour, wheat, wholemeal | C6: wholemeal flour | D6: Shop average | E6: Average of 3 supermarkets, 2 Oct 2026 | F6: Own-brand standard range where sold (see 'Shop prices' tab) | G6: 1.34 | H6: 1000 | I6: =IF(AND(ISNUMBER(G6),ISNUMBER(H6),H6>0),G6/H6*1000,"") -> 1.34 | J6: Morrisons, Sainsbury's, Tesco | K6: 02/10/2026 | L6: Range £1.00 to £1.95 per kg
A7: 11-973 | B7: Bread, naan, retail | C7: naan; naan bread | D7: Shop average | E7: Average of 3 supermarkets, 2 Oct 2026 | F7: Own-brand standard range where sold (see 'Shop prices' tab) | G7: 3.69 | H7: 1000 | I7: =IF(AND(ISNUMBER(G7),ISNUMBER(H7),H7>0),G7/H7*1000,"") -> 3.69 | J7: Morrisons, Sainsbury's, Tesco | K7: 02/10/2026 | L7: Range £2.65 to £5.77 per kg
A8: 11-974 | B8: Bread, pitta, white | C8: pitta; pitta bread | D8: Shop average | E8: Average of 3 supermarkets, 2 Oct 2026 | F8: Own-brand standard range where sold (see 'Shop prices' tab) | G8: 1.39 | H8: 1000 | I8: =IF(AND(ISNUMBER(G8),ISNUMBER(H8),H8>0),G8/H8*1000,"") -> 1.39 | J8: Morrisons, Sainsbury's, Tesco | K8: 02/10/2026 | L8: Range £1.39 to £1.39 per kg. Weight per item: 6 pittas x 60 g (Tesco product page)
A9: 12-184 | B9: Yogurt, whole milk, plain | C9: natural yogurt; natural yoghurt; plain yogurt; yogurt; yoghurt | D9: Shop average | E9: Average of 3 supermarkets, 2 Oct 2026 | F9: Own-brand standard range where sold (see 'Shop prices' tab) | G9: 2.3 | H9: 1000 | I9: =IF(AND(ISNUMBER(G9),ISNUMBER(H9),H9>0),G9/H9*1000,"") -> 2.3 | J9: Morrisons, Sainsbury's, Tesco | K9: 02/10/2026 | L9: Range £2.30 to £2.30 per kg
A10: 12-307 | B10: Milk, skimmed, pasteurised, average | C10: skimmed milk | D10: ONS stand-in, check | E10: ONS average price, Aug 2026 | F10: Milk - cow's (semi-skimmed, fresh) (1136 ml) | G10: 1.15 | H10: 1136 | I10: =IF(AND(ISNUMBER(G10),ISNUMBER(H10),H10>0),G10/H10*1000,"") -> 1.0123239 | L10: ONS has no skimmed milk item. The shop rows are 1-pint packs (£1.50/litre), which cost more per kg than the 2-pint ONS milk items. Tesco and Sainsbury's also sell 2 pints of skimmed for £1.20 (about £1.06/kg), close to the ONS semi-skimmed price used here
A11: 12-334 | B11: Cream, fresh, double, including Jersey cream | C11: double cream | D11: Shop average | E11: Average of 3 supermarkets, 2 Oct 2026 | F11: Own-brand standard range where sold (see 'Shop prices' tab) | G11: 7.56 | H11: 1000 | I11: =IF(AND(ISNUMBER(G11),ISNUMBER(H11),H11>0),G11/H11*1000,"") -> 7.56 | J11: Morrisons, Sainsbury's, Tesco | K11: 02/10/2026 | L11: Range £7.33 to £8.00 per kg
A12: 12-335 | B12: Creme fraiche, full fat | C12: creme fraiche | D12: Shop average | E12: Average of 3 supermarkets, 2 Oct 2026 | F12: Own-brand standard range where sold (see 'Shop prices' tab) | G12: 2.83 | H12: 1000 | I12: =IF(AND(ISNUMBER(G12),ISNUMBER(H12),H12>0),G12/H12*1000,"") -> 2.83 | J12: Morrisons, Sainsbury's, Tesco | K12: 02/10/2026 | L12: Range £2.50 to £3.50 per kg
A13: 12-360 | B13: Cheese, Mozzarella, fresh | C13: mozzarella | D13: Shop average | E13: Average of 3 supermarkets, 2 Oct 2026 | F13: Own-brand standard range where sold (see 'Shop prices' tab) | G13: 8.4 | H13: 1000 | I13: =IF(AND(ISNUMBER(G13),ISNUMBER(H13),H13>0),G13/H13*1000,"") -> 8.4 | J13: Morrisons, Sainsbury's, Tesco | K13: 02/10/2026 | L13: Range £4.40 to £10.40 per kg
A14: 12-379 | B14: Yogurt, low fat, plain | C14: low fat yogurt | D14: Shop average | E14: Average of 3 supermarkets, 2 Oct 2026 | F14: Own-brand standard range where sold (see 'Shop prices' tab) | G14: 1.9 | H14: 1000 | I14: =IF(AND(ISNUMBER(G14),ISNUMBER(H14),H14>0),G14/H14*1000,"") -> 1.9 | J14: Morrisons, Sainsbury's, Tesco | K14: 02/10/2026 | L14: Range £1.10 to £2.30 per kg
A15: 12-495 | B15: Cheese, Paneer | C15: paneer | D15: Shop average | E15: Average of 2 supermarkets, 2 Oct 2026 | F15: Own-brand standard range where sold (see 'Shop prices' tab) | G15: 9 | H15: 1000 | I15: =IF(AND(ISNUMBER(G15),ISNUMBER(H15),H15>0),G15/H15*1000,"") -> 9 | J15: Morrisons, Tesco | K15: 02/10/2026 | L15: Range £9.00 to £9.00 per kg
A16: 12-524 | B16: Milk, soya, non-dairy alternative to milk, unsweetened, fortified | C16: soya milk | D16: Shop average | E16: Average of 3 supermarkets, 2 Oct 2026 | F16: Own-brand standard range where sold (see 'Shop prices' tab) | G16: 1.25 | H16: 1000 | I16: =IF(AND(ISNUMBER(G16),ISNUMBER(H16),H16>0),G16/H16*1000,"") -> 1.25 | J16: Morrisons, Sainsbury's, Tesco | K16: 02/10/2026 | L16: Range £1.15 to £1.30 per kg
A17: 12-525 | B17: Cheese, Feta | C17: feta | D17: Shop average | E17: Average of 3 supermarkets, 2 Oct 2026 | F17: Own-brand standard range where sold (see 'Shop prices' tab) | G17: 11.25 | H17: 1000 | I17: =IF(AND(ISNUMBER(G17),ISNUMBER(H17),H17>0),G17/H17*1000,"") -> 11.25 | J17: Morrisons, Sainsbury's, Tesco | K17: 02/10/2026 | L17: Range £10.75 to £11.75 per kg
A18: 12-545 | B18: Cocoa powder | C18: cocoa powder | D18: Shop average | E18: Average of 3 supermarkets, 2 Oct 2026 | F18: Own-brand standard range where sold (see 'Shop prices' tab) | G18: 14.59 | H18: 1000 | I18: =IF(AND(ISNUMBER(G18),ISNUMBER(H18),H18>0),G18/H18*1000,"") -> 14.59 | J18: Morrisons, Sainsbury's, Tesco | K18: 02/10/2026 | L18: Range £11.96 to £17.80 per kg
A19: 12-555 | B19: Yogurt, Greek style, plain | C19: greek yogurt; greek yoghurt | D19: Shop average | E19: Average of 3 supermarkets, 2 Oct 2026 | F19: Own-brand standard range where sold (see 'Shop prices' tab) | G19: 2.3 | H19: 1000 | I19: =IF(AND(ISNUMBER(G19),ISNUMBER(H19),H19>0),G19/H19*1000,"") -> 2.3 | J19: Morrisons, Sainsbury's, Tesco | K19: 02/10/2026 | L19: Range £2.30 to £2.30 per kg
A20: 13-074 | B20: Beans, chick peas, Kabuli, whole, dried, raw | C20: dried chickpea | D20: Shop average | E20: Average of 3 supermarkets, 2 Oct 2026 | F20: Own-brand standard range where sold (see 'Shop prices' tab) | G20: 3.01 | H20: 1000 | I20: =IF(AND(ISNUMBER(G20),ISNUMBER(H20),H20>0),G20/H20*1000,"") -> 3.01 | J20: Morrisons, Sainsbury's, Tesco | K20: 02/10/2026 | L20: Range £1.93 to £4.60 per kg
A21: 13-089 | B21: Lentils, green and brown, whole, dried, raw | C21: green lentil; brown lentil | D21: Shop average | E21: Average of 3 supermarkets, 2 Oct 2026 | F21: Own-brand standard range where sold (see 'Shop prices' tab) | G21: 4.17 | H21: 1000 | I21: =IF(AND(ISNUMBER(G21),ISNUMBER(H21),H21>0),G21/H21*1000,"") -> 4.17 | J21: Morrisons, Sainsbury's, Tesco | K21: 02/10/2026 | L21: Range £4.10 to £4.20 per kg
A22: 13-161 | B22: Aubergine, raw | C22: aubergine; eggplant | D22: Shop average | E22: Average of 2 supermarkets, 2 Oct 2026 | F22: Own-brand standard range where sold (see 'Shop prices' tab) | G22: 1.73 | H22: 1000 | I22: =IF(AND(ISNUMBER(G22),ISNUMBER(H22),H22>0),G22/H22*1000,"") -> 1.73 | J22: Morrisons, Sainsbury's | K22: 02/10/2026 | L22: Range £1.73 to £1.73 per kg. Weight per item: USDA FDC 169228, 1 aubergine
A23: 13-164 | B23: Beetroot, raw | C23: beetroot | D23: No price yet | E23: Supermarket shelf price | I23: =IF(AND(ISNUMBER(G23),ISNUMBER(H23),H23>0),G23/H23*1000,"") | L23: Only Sainsbury's gave a weight for standard beetroot. Morrisons sells bunches with no weight, and Tesco's only beetroot sold by weight is organic, which the rules leave out
A24: 13-190 | B24: Cabbage, red, raw | C24: red cabbage | D24: Shop average | E24: Average of 3 supermarkets, 2 Oct 2026 | F24: Own-brand standard range where sold (see 'Shop prices' tab) | G24: 1.06 | H24: 1000 | I24: =IF(AND(ISNUMBER(G24),ISNUMBER(H24),H24>0),G24/H24*1000,"") -> 1.06 | J24: Morrisons, Sainsbury's, Tesco | K24: 02/10/2026 | L24: Range £1.06 to £1.06 per kg. Weight per item: USDA FDC 169977, 1 medium red cabbage head
A25: 13-234 | B25: Curly kale, raw | C25: kale | D25: Shop average | E25: Average of 2 supermarkets, 2 Oct 2026 | F25: Own-brand standard range where sold (see 'Shop prices' tab) | G25: 4.46 | H25: 1000 | I25: =IF(AND(ISNUMBER(G25),ISNUMBER(H25),H25>0),G25/H25*1000,"") -> 4.46 | J25: Morrisons, Tesco | K25: 02/10/2026 | L25: Range £4.44 to £4.47 per kg
A26: 13-244 | B26: Garlic, raw | C26: garlic; garlic clove | D26: No price yet | E26: Supermarket shelf price | I26: =IF(AND(ISNUMBER(G26),ISNUMBER(H26),H26>0),G26/H26*1000,"") | L26: Garlic is sold in bulbs with no weight shown, and USDA has no bulb weight
A27: 13-300 | B27: Okra, raw | C27: okra | D27: Shop average | E27: Average of 2 supermarkets, 2 Oct 2026 | F27: Own-brand standard range where sold (see 'Shop prices' tab) | G27: 9.38 | H27: 1000 | I27: =IF(AND(ISNUMBER(G27),ISNUMBER(H27),H27>0),G27/H27*1000,"") -> 9.38 | J27: Morrisons, Sainsbury's | K27: 02/10/2026 | L27: Range £8.75 to £10.00 per kg
A28: 13-316 | B28: Peppers, capsicum, chilli, green, raw | C28: chilli; green chilli | D28: Shop average | E28: Average of 3 supermarkets, 2 Oct 2026 | F28: Own-brand standard range where sold (see 'Shop prices' tab) | G28: 13.44 | H28: 1000 | I28: =IF(AND(ISNUMBER(G28),ISNUMBER(H28),H28>0),G28/H28*1000,"") -> 13.44 | J28: Morrisons, Sainsbury's, Tesco | K28: 02/10/2026 | L28: Range £11.54 to £14.40 per kg
A29: 13-317 | B29: Peppers, capsicum, chilli, red, raw | C29: red chilli | D29: Shop average | E29: Average of 3 supermarkets, 2 Oct 2026 | F29: Own-brand standard range where sold (see 'Shop prices' tab) | G29: 9.59 | H29: 1000 | I29: =IF(AND(ISNUMBER(G29),ISNUMBER(H29),H29>0),G29/H29*1000,"") -> 9.59 | J29: Morrisons, Sainsbury's, Tesco | K29: 02/10/2026 | L29: Range £8.46 to £11.80 per kg
A30: 13-342 | B30: Shallots, raw | C30: shallot | D30: Shop average | E30: Average of 2 supermarkets, 2 Oct 2026 | F30: Own-brand standard range where sold (see 'Shop prices' tab) | G30: 3.38 | H30: 1000 | I30: =IF(AND(ISNUMBER(G30),ISNUMBER(H30),H30>0),G30/H30*1000,"") -> 3.38 | J30: Sainsbury's, Tesco | K30: 02/10/2026 | L30: Range £3.38 to £3.38 per kg
A31: 13-352 | B31: Spring onions, bulbs and tops, raw | C31: spring onion | D31: Shop average | E31: Average of 3 supermarkets, 2 Oct 2026 | F31: Own-brand standard range where sold (see 'Shop prices' tab) | G31: 6.77 | H31: 1000 | I31: =IF(AND(ISNUMBER(G31),ISNUMBER(H31),H31>0),G31/H31*1000,"") -> 6.77 | J31: Morrisons, Sainsbury's, Tesco | K31: 02/10/2026 | L31: Range £6.50 to £6.90 per kg
A32: 13-355 | B32: Squash, butternut, raw | C32: butternut squash | D32: No price yet | E32: Supermarket shelf price | I32: =IF(AND(ISNUMBER(G32),ISNUMBER(H32),H32>0),G32/H32*1000,"") | L32: Only Sainsbury's sells it by weight. Tesco and Morrisons sell it 'each' with no weight shown
A33: 13-519 | B33: Tomatoes, cherry, raw | C33: cherry tomato | D33: Shop average | E33: Average of 3 supermarkets, 2 Oct 2026 | F33: Own-brand standard range where sold (see 'Shop prices' tab) | G33: 3.12 | H33: 1000 | I33: =IF(AND(ISNUMBER(G33),ISNUMBER(H33),H33>0),G33/H33*1000,"") -> 3.12 | J33: Morrisons, Sainsbury's, Tesco | K33: 02/10/2026 | L33: Range £2.70 to £3.33 per kg
A34: 13-521 | B34: Spinach, baby, raw | C34: baby spinach | D34: Shop average | E34: Average of 3 supermarkets, 2 Oct 2026 | F34: Own-brand standard range where sold (see 'Shop prices' tab) | G34: 7.36 | H34: 1000 | I34: =IF(AND(ISNUMBER(G34),ISNUMBER(H34),H34>0),G34/H34*1000,"") -> 7.36 | J34: Morrisons, Sainsbury's, Tesco | K34: 02/10/2026 | L34: Range £6.25 to £8.33 per kg
A35: 13-531 | B35: Tomato puree | C35: tomato puree; tomato paste | D35: Shop average | E35: Average of 3 supermarkets, 2 Oct 2026 | F35: Own-brand standard range where sold (see 'Shop prices' tab) | G35: 3.84 | H35: 1000 | I35: =IF(AND(ISNUMBER(G35),ISNUMBER(H35),H35>0),G35/H35*1000,"") -> 3.84 | J35: Morrisons, Sainsbury's, Tesco | K35: 02/10/2026 | L35: Range £2.95 to £5.63 per kg
A36: 13-570 | B36: Tofu, soya bean, steamed | C36: tofu | D36: Shop average | E36: Average of 3 supermarkets, 2 Oct 2026 | F36: Own-brand standard range where sold (see 'Shop prices' tab) | G36: 8.06 | H36: 1000 | I36: =IF(AND(ISNUMBER(G36),ISNUMBER(H36),H36>0),G36/H36*1000,"") -> 8.06 | J36: Morrisons, Sainsbury's, Tesco | K36: 02/10/2026 | L36: Range £6.67 to £8.75 per kg
A37: 13-572 | B37: Spinach, mature, raw | C37: spinach | D37: Shop average | E37: Average of 3 supermarkets, 2 Oct 2026 | F37: Own-brand standard range where sold (see 'Shop prices' tab) | G37: 4.39 | H37: 1000 | I37: =IF(AND(ISNUMBER(G37),ISNUMBER(H37),H37>0),G37/H37*1000,"") -> 4.39 | J37: Morrisons, Sainsbury's, Tesco | K37: 02/10/2026 | L37: Range £3.54 to £5.19 per kg
A38: 13-574 | B38: Quorn, pieces, as purchased | C38: quorn | D38: Shop average | E38: Average of 3 supermarkets, 2 Oct 2026 | F38: Own-brand standard range where sold (see 'Shop prices' tab) | G38: 9.17 | H38: 1000 | I38: =IF(AND(ISNUMBER(G38),ISNUMBER(H38),H38>0),G38/H38*1000,"") -> 9.17 | J38: Morrisons, Sainsbury's, Tesco | K38: 02/10/2026 | L38: Range £9.17 to £9.17 per kg
A39: 13-624 | B39: Leeks, raw | C39: leek | D39: Shop average | E39: Average of 3 supermarkets, 2 Oct 2026 | F39: Own-brand standard range where sold (see 'Shop prices' tab) | G39: 2.74 | H39: 1000 | I39: =IF(AND(ISNUMBER(G39),ISNUMBER(H39),H39>0),G39/H39*1000,"") -> 2.74 | J39: Morrisons, Sainsbury's, Tesco | K39: 02/10/2026 | L39: Range £2.74 to £2.74 per kg
A40: 13-636 | B40: Celery, raw | C40: celery | D40: Shop average | E40: Average of 3 supermarkets, 2 Oct 2026 | F40: Own-brand standard range where sold (see 'Shop prices' tab) | G40: 3.6 | H40: 1000 | I40: =IF(AND(ISNUMBER(G40),ISNUMBER(H40),H40>0),G40/H40*1000,"") -> 3.6 | J40: Morrisons, Sainsbury's, Tesco | K40: 02/10/2026 | L40: Range £3.60 to £3.60 per kg
...

Sheet Shop prices
A1: Food code | B1: Shop | C1: Product | D1: Pack price (£) | E1: Pack size | F1: Pack weight (g) | G1: Unit price shown | H1: Price per kg (£) | I1: How per kg was worked out | J1: Used | K1: URL | L1: Checked | M1: Note
A2: 11-861 | B2: Morrisons | C2: Morrisons Easy Cook Long Grain Rice 500g | D2: 1 | E2: 500g | F2: 500 | G2: £2.00/kg | H2: 2 | I2: pack price / pack weight | J2: yes | K2: https://groceries.morrisons.com/search?q=long%20grain%20rice | L2: 2026-10-02 | M2: Easy cook (parboiled); no plain own-brand long grain seen; 'white rice' search returned 403 twice. 1kg pack is £1.25 (£1.25/kg, Unbeatable Price)
A3: 11-861 | B3: Sainsbury's | C3: Sainsbury's Long Grain Rice 1kg | D3: 1.3 | E3: 1kg | F3: 1000 | G3: £1.30/kg | H3: 1.3 | I3: pack price / pack weight | J3: yes | K3: https://www.sainsburys.co.uk/gol-ui/SearchResults/long%20grain%20rice | L3: 2026-10-02 | M3: Plain long grain; smallest pack of this line
A4: 11-861 | B4: Tesco | C4: Tesco Easy Cook Long Grain Rice 1Kg | D4: 1.25 | E4: 1Kg | F4: 1000 | G4: £1.25/kg | H4: 1.25 | I4: pack price / pack weight | J4: yes | K4: https://www.tesco.com/groceries/en-GB/search?query=long%20grain%20rice | L4: 2026-10-02 | M4: Easy cook (parboiled); no plain Tesco long grain white rice listed (checked second search). Aldi Price Match badge
A5: 11-868 | B5: Morrisons | C5: Morrisons Easy Cook Brown Long Grain Rice | D5: 1.39 | E5: 1kg | F5: 1000 | G5: £1.39/kg | H5: 1.39 | I5: pack price / pack weight | J5: yes | K5: https://groceries.morrisons.com/products/morrisons-easy-cook-brown-long-grain-rice/104552192 | L5: 2026-10-02 | M5: Easy cook; first fetch misread unit as £1.20/kg, re-check shows 'Ordinarily £1.39/kg'
A6: 11-868 | B6: Sainsbury's | C6: Sainsbury's Brown Rice 500g | D6: 0.69 | E6: 500g | F6: 500 | G6: £1.38/kg | H6: 1.38 | I6: pack price / pack weight | J6: yes | K6: https://www.sainsburys.co.uk/gol-ui/SearchResults/brown%20rice | L6: 2026-10-02 | M6: Aldi price match
A7: 11-868 | B7: Tesco | C7: Tesco Easy Cook Brown Rice 1Kg | D7: 1.39 | E7: 1Kg | F7: 1000 | G7: £1.39/kg | H7: 1.39 | I7: pack price / pack weight | J7: yes | K7: https://www.tesco.com/groceries/en-GB/search?query=brown%20rice | L7: 2026-10-02 | M7: Easy cook brown rice; no other Tesco plain brown rice in results (2Kg £2.85 larger)
A8: 11-878 | B8: Morrisons | C8: Gallo Traditional Risotto 500g | D8: 3 | E8: 500g | F8: 500 | G8: £6.00/kg | H8: 6 | I8: pack price / pack weight | J8: yes | K8: https://groceries.morrisons.com/search?q=risotto%20rice | L8: 2026-10-02 | M8: branded; no Morrisons own-brand risotto/arborio rice found; Riso Gallo Easy Cook Risotto Rice 500g £2.65 also listed but is easy-cook not plain
A9: 11-878 | B9: Sainsbury's | C9: Sainsbury's Arborio Risotto Rice 500g | D9: 2.25 | E9: 500g | F9: 500 | G9: £4.50 / kg | H9: 4.5 | I9: pack price / pack weight | J9: yes | K9: https://www.sainsburys.co.uk/gol-ui/SearchResults/arborio%20rice | L9: 2026-10-02
A10: 11-878 | B10: Tesco | C10: Tesco Risotto Rice 1Kg | D10: 3.3 | E10: 1Kg | F10: 1000 | G10: £3.30/kg | H10: 3.3 | I10: pack price / pack weight | J10: yes | K10: https://www.tesco.com/groceries/en-GB/search?query=risotto%20rice | L10: 2026-10-02 | M10: Only Tesco standard risotto rice listed; name does not say Arborio; 1kg is the only size
A11: 11-889 | B11: Morrisons | C11: Allinson's Very Strong Wholemeal Bread Flour | D11: 1.95 | E11: 1kg | F11: 1000 | G11: £1.95/kg | H11: 1.95 | I11: pack price / pack weight | J11: yes | K11: https://groceries.morrisons.com/search?q=strong%20wholemeal%20flour | L11: 2026-10-02 | M11: branded; no Morrisons own-brand wholemeal flour found (Morrisons Strong Brown Flour 1.5kg £1.60 is brown not wholemeal)
A12: 11-889 | B12: Sainsbury's | C12: Sainsbury's Strong Stoneground 100% Wholemeal Flour 1.5kg | D12: 1.5 | E12: 1.5kg | F12: 1500 | G12: £1.00/kg | H12: 1 | I12: pack price / pack weight | J12: yes | K12: https://www.sainsburys.co.uk/gol-ui/SearchResults/sainsbury's%20wholemeal%20flour | L12: 2026-10-02 | M12: strong (bread) wholemeal; no own-brand plain wholemeal found
A13: 11-889 | B13: Tesco | C13: Wrights Strong Wholemeal Bread Flour 1.5Kg | D13: 1.6 | E13: 1.5Kg | F13: 1500 | G13: £1.07/kg | H13: 1.07 | I13: pack price / pack weight | J13: yes | K13: https://www.tesco.com/groceries/en-GB/search?query=strong%20wholemeal%20bread%20flour | L13: 2026-10-02 | M13: branded; no Tesco own-brand wholemeal flour found except Tesco Wholemeal Chapatti Flour 10Kg (£7.50, not a household pack); Hovis Strong Wholemeal 1kg also £1.60 (£1.60/kg)
A14: 11-973 | B14: Morrisons | C14: Morrisons Plain Naan Bread | D14: 1.5 | E14: 2 x 130g | F14: 260 | G14: £5.77/kg | H14: 5.77 | I14: pack price / pack weight | J14: yes | K14: https://groceries.morrisons.com/search?q=naan%20bread | L14: 2026-10-02
A15: 11-973 | B15: Sainsbury's | C15: Sainsbury's Plain Naan x2 260g | D15: 0.69 | E15: x2 260g | F15: 260 | G15: £2.65/kg | H15: 2.65 | I15: pack price / pack weight | J15: yes | K15: https://www.sainsburys.co.uk/gol-ui/SearchResults/naan%20bread | L15: 2026-10-02 | M15: Aldi price match; Sainsbury's Indian Plain Naan x2 260g also listed at £1.50 (£5.77/kg)
A16: 11-973 | B16: Tesco | C16: Tesco Plain Naans 2 Pack 260G | D16: 0.69 | E16: 260G (2 pack) | F16: 260 | G16: £2.65/kg | H16: 2.65 | I16: pack price / pack weight | J16: yes | K16: https://www.tesco.com/groceries/en-GB/search?query=naan%20bread | L16: 2026-10-02 | M16: Aldi Price Match line; Tesco also lists 'Tesco Plain Naan Bread 2 Pack' £1.50 (£0.75/each, Clubcard £1.00) with no weight shown
A17: 11-974 | B17: Morrisons | C17: Morrisons Stonebaked White Pittas 6 Pack | D17: 0.5 | E17: 6 per pack | G17: 8.3p/item | H17: 1.39 | I17: price each / 360 g (6 pittas x 60 g (Tesco product page)) | J17: yes | K17: https://groceries.morrisons.com/products/morrisons-stonebaked-white-pittas-6-pack/109515964 | L17: 2026-10-02 | M17: 6 pittas; product page states no net weight. Unbeatable Price
A18: 11-974 | B18: Sainsbury's | C18: Sainsbury's White Pittas x6 | D18: 0.5 | E18: x6 | G18: 8p per unit | H18: 1.39 | I18: price each / 360 g (6 pittas x 60 g (Tesco product page)) | J18: yes | K18: https://www.sainsburys.co.uk/gol-ui/SearchResults/white%20pitta%20bread | L18: 2026-10-02 | M18: 6 pittas; no pack weight shown on search page. Aldi price match
A19: 11-974 | B19: Tesco | C19: Tesco White Plain Pitta Bread 6 Pack | D19: 0.5 | E19: 6 pack | G19: £0.08/each | H19: 1.39 | I19: price each / 360 g (6 pittas x 60 g (Tesco product page)) | J19: yes | K19: https://www.tesco.com/shop/en-GB/products/254945564 | L19: 2026-10-02 | M19: 6 pittas; no net pack weight stated; product page nutrition is per pitta 60g. Aldi Price Match
A20: 12-184 | B20: Morrisons | C20: Morrisons Natural Yogurt | D20: 1.15 | E20: 500g | F20: 500 | G20: £2.30/kg | H20: 2.3 | I20: pack price / pack weight | J20: yes | K20: https://groceries.morrisons.com/products/morrisons-natural-yogurt/103145923 | L20: 2026-10-02 | M20: Fat level not stated; Morrisons also sells Whole Milk Natural Yoghurt 1kg £2.00 (£2.00/kg) which is explicitly whole milk
A21: 12-184 | B21: Sainsbury's | C21: Sainsbury's Natural Yogurt 500g | D21: 1.15 | E21: 500g | F21: 500 | G21: £2.30/kg | H21: 2.3 | I21: pack price / pack weight | J21: yes | K21: https://www.sainsburys.co.uk/gol-ui/SearchResults/natural%20yogurt | L21: 2026-10-02 | M21: Fat level not stated on search page (fat free / low fat versions are labelled separately)
A22: 12-184 | B22: Tesco | C22: Tesco Natural Yogurt 500G | D22: 1.15 | E22: 500G | F22: 500 | G22: £2.30/kg | H22: 2.3 | I22: pack price / pack weight | J22: yes | K22: https://www.tesco.com/groceries/en-GB/search?query=natural%20yogurt | L22: 2026-10-02 | M22: Fat level not stated on search page (low fat / 0% versions are labelled separately)
A23: 12-307 | B23: Morrisons | C23: Morrisons Skimmed British Milk 1 Pint | D23: 0.85 | E23: 568ml | F23: 568 | G23: £1.50/litre | H23: 1.5 | I23: pack price / pack weight (not used: this food's price comes from elsewhere, or too few shops) | J23: no | K23: https://groceries.morrisons.com/search?q=skimmed%20milk | L23: 2026-10-02 | M23: "Unbeatable Price" label; 500ml bottle £0.95 also listed (on-the-go size, not used)
A24: 12-307 | B24: Sainsbury's | C24: Sainsbury's British Skimmed Milk 568ml (1 pint) | D24: 0.85 | E24: 568ml | F24: 568 | G24: £1.50 / ltr | H24: 1.5 | I24: pack price / pack weight (not used: this food's price comes from elsewhere, or too few shops) | J24: no | K24: https://www.sainsburys.co.uk/gol-ui/SearchResults/skimmed%20milk | L24: 2026-10-02 | M24: 2 pint 1.13L £1.20 also available
A25: 12-307 | B25: Tesco | C25: Tesco British Skimmed Milk 568Ml, 1 Pint | D25: 0.85 | E25: 568ml | F25: 568 | G25: £1.50/litre | H25: 1.5 | I25: pack price / pack weight (not used: this food's price comes from elsewhere, or too few shops) | J25: no | K25: https://www.tesco.com/groceries/en-GB/search?query=skimmed%20milk | L25: 2026-10-02 | M25: 2 pint 1.136L £1.20 also available
A26: 12-334 | B26: Morrisons | C26: Morrisons British Double Cream | D26: 1.1 | E26: 150ml | F26: 150 | G26: £7.33/litre | H26: 7.33 | I26: pack price / pack weight | J26: yes | K26: https://groceries.morrisons.com/search?q=double%20cream | L26: 2026-10-02 | M26: labelled Unbeatable Price; 300ml £1.70 (£5.67/litre)
A27: 12-334 | B27: Sainsbury's | C27: Sainsbury's British Double Cream 150ml | D27: 1.2 | E27: 150ml | F27: 150 | G27: £8.00/ltr | H27: 8 | I27: pack price / pack weight | J27: yes | K27: https://www.sainsburys.co.uk/gol-ui/SearchResults/double%20cream | L27: 2026-10-02 | M27: 300ml £1.70 (£5.67/ltr)
A28: 12-334 | B28: Tesco | C28: Tesco British Double Cream 150Ml | D28: 1.1 | E28: 150Ml | F28: 150 | G28: £7.33/litre | H28: 7.33 | I28: pack price / pack weight | J28: yes | K28: https://www.tesco.com/groceries/en-GB/search?query=double%20cream | L28: 2026-10-02 | M28: 300ml £1.70 (£5.67/litre)
A29: 12-335 | B29: Morrisons | C29: Morrisons British Creme Fraiche | D29: 0.75 | E29: 300ml | F29: 300 | G29: £2.50/litre | H29: 2.5 | I29: pack price / pack weight | J29: yes | K29: https://groceries.morrisons.com/search?q=fresh%20creme%20fraiche | L29: 2026-10-02 | M29: 'creme fraiche' search returned 403 twice; this result from search 'fresh creme fraiche'; tagged Unbeatable Price
A30: 12-335 | B30: Sainsbury's | C30: Sainsbury's British Crème Fraîche 300ml | D30: 1.05 | E30: 300ml | F30: 300 | G30: £3.50/ltr | H30: 3.5 | I30: pack price / pack weight | J30: yes | K30: https://www.sainsburys.co.uk/gol-ui/SearchResults/creme%20fraiche | L30: 2026-10-02
A31: 12-335 | B31: Tesco | C31: Tesco British Creme Fraiche 300ml | D31: 0.75 | E31: 300ml | F31: 300 | G31: £2.50/litre | H31: 2.5 | I31: pack price / pack weight | J31: yes | K31: https://www.tesco.com/groceries/en-GB/search?query=creme%20fraiche | L31: 2026-10-02 | M31: Aldi Price Match
A32: 12-360 | B32: Morrisons | C32: Morrisons Mozzarella 125g | D32: 1.3 | E32: 125g | F32: 125 | G32: £10.40/kg | H32: 10.4 | I32: pack price / pack weight | J32: yes | K32: https://groceries.morrisons.com/search?q=mozzarella | L32: 2026-10-02
A33: 12-360 | B33: Sainsbury's | C33: Castelli 210g Mozzarella Cheese | D33: 0.55 | E33: 210g | F33: 125 | G33: £4.40/kg | H33: 4.4 | I33: pack price / pack weight | J33: yes | K33: https://www.sainsburys.co.uk/gol-ui/SearchResults/mozzarella | L33: 2026-10-02 | M33: DOUBTFUL. branded: no standard Sainsbury's mozzarella ball listed (only Lighter 125g £1.45, pearls, grated, TTD buffalo). Castelli is cheapest branded; pack_grams 125 inferred from unit price (drained), not stated. Galbani Italian Mozzarella 125g is £1.95 (£15.60/kg)
A34: 12-360 | B34: Tesco | C34: Tesco Mozzarella 200g | D34: 1.3 | E34: 200g (unit price on drained weight) | F34: 125 | G34: £10.40/kg DR.WT | H34: 10.4 | I34: pack price / pack weight | J34: yes | K34: https://www.tesco.com/groceries/en-GB/search?query=mozzarella | L34: 2026-10-02 | M34: Ball in brine; pack_grams = drained weight implied by DR.WT unit price (1.30/10.40 = 125 g)
A35: 12-379 | B35: Morrisons | C35: Morrisons Low Fat Natural Yogurt | D35: 1.15 | E35: 500g | F35: 500 | G35: £2.30/kg | H35: 2.3 | I35: pack price / pack weight | J35: yes | K35: https://groceries.morrisons.com/products/morrisons-low-fat-natural-yogurt/103149414 | L35: 2026-10-02
A36: 12-379 | B36: Sainsbury's | C36: Sainsbury's Fat Free Natural Yogurt 500g | D36: 0.55 | E36: 500g | F36: 500 | G36: £1.10/kg | H36: 1.1 | I36: pack price / pack weight | J36: yes | K36: https://www.sainsburys.co.uk/gol-ui/SearchResults/low%20fat%20natural%20yogurt | L36: 2026-10-02 | M36: DOUBTFUL: no Sainsbury's plain low fat natural yogurt found (only Greek Style Low Fat 500g £1.15); this is fat free; Aldi price match
A37: 12-379 | B37: Tesco | C37: Tesco 0% Fat Natural Yogurt 500G | D37: 1.15 | E37: 500G | F37: 500 | G37: £2.30/kg | H37: 2.3 | I37: pack price / pack weight | J37: yes | K37: https://www.tesco.com/groceries/en-GB/search?query=low%20fat%20natural%20yogurt | L37: 2026-10-02 | M37: DOUBTFUL: no Tesco standard 'low fat' natural yogurt; this is fat free. Creamfields Low Fat Natural Yogurt 500G £0.55 is a value range (excluded)
A38: 12-495 | B38: Morrisons | C38: Morrisons Paneer 200g | D38: 1.8 | E38: 200g | F38: 200 | G38: £9.00/kg | H38: 9 | I38: pack price / pack weight | J38: yes | K38: https://groceries.morrisons.com/search?q=paneer | L38: 2026-10-02
A39: 12-495 | B39: Sainsbury's | I39: no price found | J39: no | K39: https://www.sainsburys.co.uk/gol-ui/SearchResults/paneer | L39: 2026-10-02 | M39: Page returned no products (JavaScript-only shell) on 2 attempts
A40: 12-495 | B40: Tesco | C40: Tesco Paneer Cheese 200G | D40: 1.8 | E40: 200G | F40: 200 | G40: £9.00/kg | H40: 9 | I40: pack price / pack weight | J40: yes | K40: https://www.tesco.com/groceries/en-GB/search?query=paneer | L40: 2026-10-02
...

Sheet ONS items used
A1: ONS item | B1: ONS pack size | C1: Average price Aug 2026 (£) | D1: Used for these food codes
A2: Apples - not cooking | B2: 1000 g | C2: 2.25 | D2: 14-319
A3: Baked beans | B3: 425 g | C3: 0.89 | D3: 13-532
A4: Bananas | B4: 1000 g | C4: 1.14 | D4: 14-318
A5: Beans - fresh (excl. soya or edamame) | B5: 1000 g | C5: 5.32 | D5: 13-514
A6: Beef - minced or diced | B6: 1000 g | C6: 10.96 | D6: 18-007, 18-077, 18-469, 18-508
A7: Beef - steak or chops | B7: 1000 g | C7: 23.24 | D7: 18-065, 18-471
A8: Blueberries | B8: 1000 g | C8: 10.59 | D8: 14-325
A9: Bread - sliced white | B9: 800 g | C9: 1.34 | D9: 11-980
A10: Bread - sliced wholemeal or brown | B10: 800 g | C10: 1.3 | D10: 11-981
A11: Broccoli | B11: 1000 g | C11: 2.7 | D11: 13-502
A12: Butter - dairy (block or tub) | B12: 250 g | C12: 2.26 | D12: 17-661, 17-685
A13: Carrots | B13: 1000 g | C13: 0.94 | D13: 13-496
... A57: Wraps and tortillas (without filling) | B57: 360 g | C57: 1.5 | D57: 11-925
A59: Source: Office for National Statistics, Shopping prices comparison tool, average prices, Aug 2026. Data file avgprice.csv and metadata.csv from github.com/ONSvisual/cpi-items-actions (the repository behind the ONS tool, updated 27 Sep 2026).
A60: Tool: https://www.ons.gov.uk/economy/inflationandpriceindices/articles/shoppingpricescomparisontool/2023-05-03
A61: Contains public sector information licensed under the Open Government Licence v3.0.
A62: ONS averages are across shops and brands. From March 2026 many food prices include supermarket scanner data.
